ERROR:urlparser:Error
Traceback (most recent call last):
  File "/root/python/OTUS/otus_links/urlparser/parser.py", line 29, in key_controls
    key = int(input())
ValueError: invalid literal for int() with base 10: 'asd'
ERROR:urlparser:Error
Traceback (most recent call last):
  File "/root/python/OTUS/otus_links/urlparser/parser.py", line 29, in key_controls
    key = int(input())
KeyboardInterrupt
ERROR:urlparser:KeyboardInterrupt
Traceback (most recent call last):
  File "/root/python/OTUS/otus_links/urlparser/parser.py", line 34, in key_controls
    key = int(input())
KeyboardInterrupt
ERROR:urlparser:KeyboardInterrupt
Traceback (most recent call last):
  File "/root/python/OTUS/otus_links/urlparser/parser.py", line 34, in key_controls
    key = int(input())
KeyboardInterrupt
ERROR:urlparser:KeyboardInterrupt
Traceback (most recent call last):
  File "/root/python/OTUS/otus_links/urlparser/parser.py", line 35, in key_controls
    key = int(input())
KeyboardInterrupt
ERROR:urlparser:KeyboardInterrupt
Traceback (most recent call last):
  File "/root/python/OTUS/otus_links/urlparser/parser.py", line 35, in key_controls
    key = int(input())
KeyboardInterrupt
ERROR:urlparser:asd
NoneType: None
ERROR:urlparser:text
NoneType: None
ERROR:urlparser:text
NoneType: None
ERROR:urlparser:KeyboardInterrupt
Traceback (most recent call last):
  File "/root/python/OTUS/otus_links/urlparser/parser.py", line 34, in key_controls
    key = int(input())
KeyboardInterrupt
ERROR:urlparser:KeyboardInterrupt
Traceback (most recent call last):
  File "/root/python/OTUS/otus_links/urlparser/parser.py", line 34, in key_controls
    key = int(input())
KeyboardInterrupt
ERROR:urlparser:KeyboardInterrupt
Traceback (most recent call last):
  File "/root/python/OTUS/otus_links/urlparser/parser.py", line 34, in key_controls
    key = int(input())
KeyboardInterrupt
ERROR:urlparser:KeyboardInterrupt
Traceback (most recent call last):
  File "/root/python/OTUS/otus_links/urlparser/parser.py", line 34, in key_controls
    key = int(input())
KeyboardInterrupt
ERROR:urlparser:KeyboardInterrupt
Traceback (most recent call last):
  File "/root/python/OTUS/otus_links/urlparser/parser.py", line 34, in key_controls
    key = int(input())
KeyboardInterrupt
ERROR:urlparser:KeyboardInterrupt
Traceback (most recent call last):
  File "/root/python/OTUS/otus_links/urlparser/parser.py", line 34, in key_controls
    key = int(input())
KeyboardInterrupt
ERROR:urlparser:KeyboardInterrupt
Traceback (most recent call last):
  File "/root/python/OTUS/otus_links/urlparser/parser.py", line 34, in key_controls
    key = int(input())
KeyboardInterrupt
ERROR:urlparser:KeyboardInterrupt
Traceback (most recent call last):
  File "/root/python/OTUS/otus_links/urlparser/parser.py", line 34, in key_controls
    key = int(input())
KeyboardInterrupt
ERROR:urlparser:KeyboardInterrupt
Traceback (most recent call last):
  File "/root/python/OTUS/otus_links/urlparser/parser.py", line 34, in key_controls
    key = int(input())
KeyboardInterrupt
ERROR:urlparser:ValueError
Traceback (most recent call last):
  File "/root/python/OTUS/otus_links/urlparser/parser.py", line 34, in key_controls
    key = int(input())
ValueError: invalid literal for int() with base 10: 'asd'
ERROR:urlparser:ValueError
Traceback (most recent call last):
  File "/root/python/OTUS/otus_links/urlparser/parser.py", line 34, in key_controls
    key = int(input())
ValueError: invalid literal for int() with base 10: 'asd'
ERROR:urlparser:ValueError
Traceback (most recent call last):
  File "/root/python/OTUS/otus_links/urlparser/parser.py", line 34, in key_controls
    key = int(input())
ValueError: invalid literal for int() with base 10: 'asd'
ERROR:urlparser:KeyboardInterrupt
Traceback (most recent call last):
  File "/root/python/OTUS/otus_links/urlparser/parser.py", line 34, in key_controls
    key = int(input())
KeyboardInterrupt
ERROR:urlparser:ValueError
Traceback (most recent call last):
  File "/root/python/OTUS/otus_links/urlparser/parser.py", line 34, in key_controls
    key = int(input())
ValueError: invalid literal for int() with base 10: 'asd'
ERROR:urlparser:ValueError
Traceback (most recent call last):
  File "/root/python/OTUS/otus_links/urlparser/parser.py", line 34, in key_controls
    key = int(input())
ValueError: invalid literal for int() with base 10: 'asd'
ERROR:urlparser:KeyboardInterrupt
Traceback (most recent call last):
  File "/root/python/OTUS/otus_links/urlparser/parser.py", line 34, in key_controls
    key = int(input())
KeyboardInterrupt
ERROR:urlparser:KeyboardInterrupt
Traceback (most recent call last):
  File "/root/python/OTUS/otus_links/urlparser/parser.py", line 34, in key_controls
    key = int(input())
KeyboardInterrupt
ERROR:urlparser:KeyboardInterrupt
Traceback (most recent call last):
  File "/root/python/OTUS/otus_links/urlparser/parser.py", line 34, in key_controls
    key = int(input())
KeyboardInterrupt
ERROR:urlparser:ValueError
Traceback (most recent call last):
  File "/root/python/OTUS/otus_links/urlparser/parser.py", line 34, in key_controls
    key = int(input())
ValueError: invalid literal for int() with base 10: ''
ERROR:urlparser:ValueError
Traceback (most recent call last):
  File "/root/python/OTUS/otus_links/urlparser/parser.py", line 34, in key_controls
    key = int(input())
ValueError: invalid literal for int() with base 10: ''
ERROR:urlparser:ValueError
Traceback (most recent call last):
  File "/root/python/OTUS/otus_links/urlparser/parser.py", line 34, in key_controls
    key = int(input())
ValueError: invalid literal for int() with base 10: 'asd'
ERROR:urlparser:ValueError
Traceback (most recent call last):
  File "/root/python/OTUS/otus_links/urlparser/parser.py", line 34, in key_controls
    key = int(input())
ValueError: invalid literal for int() with base 10: 'asd'
ERROR:urlparser:KeyboardInterrupt
Traceback (most recent call last):
  File "/root/python/OTUS/otus_links/urlparser/parser.py", line 34, in key_controls
    key = int(input())
KeyboardInterrupt
ERROR:urlparser:KeyboardInterrupt
Traceback (most recent call last):
  File "/root/python/OTUS/otus_links/urlparser/parser.py", line 34, in key_controls
    key = int(input())
KeyboardInterrupt
ERROR:urlparser:ValueError
Traceback (most recent call last):
  File "/root/python/OTUS/otus_links/urlparser/parser.py", line 38, in key_controls
    key = int(input())
ValueError: invalid literal for int() with base 10: 'asd'
ERROR:urlparser:ValueError
Traceback (most recent call last):
  File "/root/python/OTUS/otus_links/urlparser/parser.py", line 37, in __key_controls
    key = int(input())
ValueError: invalid literal for int() with base 10: 'asd'
ERROR:urlparser:ValueError
Traceback (most recent call last):
  File "/root/python/OTUS/otus_links/urlparser/parser.py", line 37, in __key_controls
    key = int(input())
ValueError: invalid literal for int() with base 10: 'asd'
ERROR:urlparser:ValueError
Traceback (most recent call last):
  File "/root/python/OTUS/otus_links/urlparser/parser.py", line 37, in __key_controls
    key = int(input())
ValueError: invalid literal for int() with base 10: 'jhkjh'
ERROR:urlparser:ConnectionError
Traceback (most recent call last):
  File "/root/python/OTUS/otus_links/env/lib64/python3.6/site-packages/urllib3/connectionpool.py", line 672, in urlopen
    chunked=chunked,
  File "/root/python/OTUS/otus_links/env/lib64/python3.6/site-packages/urllib3/connectionpool.py", line 421, in _make_request
    six.raise_from(e, None)
  File "<string>", line 3, in raise_from
  File "/root/python/OTUS/otus_links/env/lib64/python3.6/site-packages/urllib3/connectionpool.py", line 416, in _make_request
    httplib_response = conn.getresponse()
  File "/usr/lib64/python3.6/http/client.py", line 1346, in getresponse
    response.begin()
  File "/usr/lib64/python3.6/http/client.py", line 307, in begin
    version, status, reason = self._read_status()
  File "/usr/lib64/python3.6/http/client.py", line 276, in _read_status
    raise RemoteDisconnected("Remote end closed connection without"
http.client.RemoteDisconnected: Remote end closed connection without response

During handling of the above exception, another exception occurred:

Traceback (most recent call last):
  File "/root/python/OTUS/otus_links/env/lib64/python3.6/site-packages/requests/adapters.py", line 449, in send
    timeout=timeout
  File "/root/python/OTUS/otus_links/env/lib64/python3.6/site-packages/urllib3/connectionpool.py", line 720, in urlopen
    method, url, error=e, _pool=self, _stacktrace=sys.exc_info()[2]
  File "/root/python/OTUS/otus_links/env/lib64/python3.6/site-packages/urllib3/util/retry.py", line 400, in increment
    raise six.reraise(type(error), error, _stacktrace)
  File "/root/python/OTUS/otus_links/env/lib64/python3.6/site-packages/urllib3/packages/six.py", line 734, in reraise
    raise value.with_traceback(tb)
  File "/root/python/OTUS/otus_links/env/lib64/python3.6/site-packages/urllib3/connectionpool.py", line 672, in urlopen
    chunked=chunked,
  File "/root/python/OTUS/otus_links/env/lib64/python3.6/site-packages/urllib3/connectionpool.py", line 421, in _make_request
    six.raise_from(e, None)
  File "<string>", line 3, in raise_from
  File "/root/python/OTUS/otus_links/env/lib64/python3.6/site-packages/urllib3/connectionpool.py", line 416, in _make_request
    httplib_response = conn.getresponse()
  File "/usr/lib64/python3.6/http/client.py", line 1346, in getresponse
    response.begin()
  File "/usr/lib64/python3.6/http/client.py", line 307, in begin
    version, status, reason = self._read_status()
  File "/usr/lib64/python3.6/http/client.py", line 276, in _read_status
    raise RemoteDisconnected("Remote end closed connection without"
urllib3.exceptions.ProtocolError: ('Connection aborted.', RemoteDisconnected('Remote end closed connection without response',))

During handling of the above exception, another exception occurred:

Traceback (most recent call last):
  File "/root/python/OTUS/otus_links/urlparser/parser.py", line 86, in get_links
    page = requests.get(url, timeout=5).text
  File "/root/python/OTUS/otus_links/env/lib64/python3.6/site-packages/requests/api.py", line 75, in get
    return request('get', url, params=params, **kwargs)
  File "/root/python/OTUS/otus_links/env/lib64/python3.6/site-packages/requests/api.py", line 60, in request
    return session.request(method=method, url=url, **kwargs)
  File "/root/python/OTUS/otus_links/env/lib64/python3.6/site-packages/requests/sessions.py", line 533, in request
    resp = self.send(prep, **send_kwargs)
  File "/root/python/OTUS/otus_links/env/lib64/python3.6/site-packages/requests/sessions.py", line 646, in send
    r = adapter.send(request, **kwargs)
  File "/root/python/OTUS/otus_links/env/lib64/python3.6/site-packages/requests/adapters.py", line 498, in send
    raise ConnectionError(err, request=request)
requests.exceptions.ConnectionError: ('Connection aborted.', RemoteDisconnected('Remote end closed connection without response',))
ERROR:urlparser:ConnectionError
Traceback (most recent call last):
  File "/root/python/OTUS/otus_links/env/lib64/python3.6/site-packages/urllib3/connectionpool.py", line 672, in urlopen
    chunked=chunked,
  File "/root/python/OTUS/otus_links/env/lib64/python3.6/site-packages/urllib3/connectionpool.py", line 421, in _make_request
    six.raise_from(e, None)
  File "<string>", line 3, in raise_from
  File "/root/python/OTUS/otus_links/env/lib64/python3.6/site-packages/urllib3/connectionpool.py", line 416, in _make_request
    httplib_response = conn.getresponse()
  File "/usr/lib64/python3.6/http/client.py", line 1346, in getresponse
    response.begin()
  File "/usr/lib64/python3.6/http/client.py", line 307, in begin
    version, status, reason = self._read_status()
  File "/usr/lib64/python3.6/http/client.py", line 276, in _read_status
    raise RemoteDisconnected("Remote end closed connection without"
http.client.RemoteDisconnected: Remote end closed connection without response

During handling of the above exception, another exception occurred:

Traceback (most recent call last):
  File "/root/python/OTUS/otus_links/env/lib64/python3.6/site-packages/requests/adapters.py", line 449, in send
    timeout=timeout
  File "/root/python/OTUS/otus_links/env/lib64/python3.6/site-packages/urllib3/connectionpool.py", line 720, in urlopen
    method, url, error=e, _pool=self, _stacktrace=sys.exc_info()[2]
  File "/root/python/OTUS/otus_links/env/lib64/python3.6/site-packages/urllib3/util/retry.py", line 400, in increment
    raise six.reraise(type(error), error, _stacktrace)
  File "/root/python/OTUS/otus_links/env/lib64/python3.6/site-packages/urllib3/packages/six.py", line 734, in reraise
    raise value.with_traceback(tb)
  File "/root/python/OTUS/otus_links/env/lib64/python3.6/site-packages/urllib3/connectionpool.py", line 672, in urlopen
    chunked=chunked,
  File "/root/python/OTUS/otus_links/env/lib64/python3.6/site-packages/urllib3/connectionpool.py", line 421, in _make_request
    six.raise_from(e, None)
  File "<string>", line 3, in raise_from
  File "/root/python/OTUS/otus_links/env/lib64/python3.6/site-packages/urllib3/connectionpool.py", line 416, in _make_request
    httplib_response = conn.getresponse()
  File "/usr/lib64/python3.6/http/client.py", line 1346, in getresponse
    response.begin()
  File "/usr/lib64/python3.6/http/client.py", line 307, in begin
    version, status, reason = self._read_status()
  File "/usr/lib64/python3.6/http/client.py", line 276, in _read_status
    raise RemoteDisconnected("Remote end closed connection without"
urllib3.exceptions.ProtocolError: ('Connection aborted.', RemoteDisconnected('Remote end closed connection without response',))

During handling of the above exception, another exception occurred:

Traceback (most recent call last):
  File "/root/python/OTUS/otus_links/urlparser/parser.py", line 86, in get_links
    page = requests.get(url, timeout=5).text
  File "/root/python/OTUS/otus_links/env/lib64/python3.6/site-packages/requests/api.py", line 75, in get
    return request('get', url, params=params, **kwargs)
  File "/root/python/OTUS/otus_links/env/lib64/python3.6/site-packages/requests/api.py", line 60, in request
    return session.request(method=method, url=url, **kwargs)
  File "/root/python/OTUS/otus_links/env/lib64/python3.6/site-packages/requests/sessions.py", line 533, in request
    resp = self.send(prep, **send_kwargs)
  File "/root/python/OTUS/otus_links/env/lib64/python3.6/site-packages/requests/sessions.py", line 646, in send
    r = adapter.send(request, **kwargs)
  File "/root/python/OTUS/otus_links/env/lib64/python3.6/site-packages/requests/adapters.py", line 498, in send
    raise ConnectionError(err, request=request)
requests.exceptions.ConnectionError: ('Connection aborted.', RemoteDisconnected('Remote end closed connection without response',))
